WARNING 2023-04-14 21:04:04,499 module : log.py / line 241  - message : Unauthorized: /events/ <WSGIRequest: GET '/events/?search=compagnie'> 
WARNING 2023-04-14 21:04:14,151 module : log.py / line 241  - message : Forbidden: /events/ <WSGIRequest: GET '/events/?search=compagnie'> 
ERROR 2023-04-14 21:05:22,085 module : log.py / line 241  - message : Internal Server Error: /clients/ <WSGIRequest: GET '/clients/?search=test'> 
Traceback (most recent call last):
  File "/Library/Frameworks/Python.framework/Versions/3.8/lib/python3.8/site-packages/django/core/handlers/exception.py", line 55, in inner
    response = get_response(request)
  File "/Library/Frameworks/Python.framework/Versions/3.8/lib/python3.8/site-packages/django/core/handlers/base.py", line 197, in _get_response
    response = wrapped_callback(request, *callback_args, **callback_kwargs)
  File "/Library/Frameworks/Python.framework/Versions/3.8/lib/python3.8/site-packages/django/views/decorators/csrf.py", line 54, in wrapped_view
    return view_func(*args, **kwargs)
  File "/Library/Frameworks/Python.framework/Versions/3.8/lib/python3.8/site-packages/rest_framework/viewsets.py", line 125, in view
    return self.dispatch(request, *args, **kwargs)
  File "/Library/Frameworks/Python.framework/Versions/3.8/lib/python3.8/site-packages/rest_framework/views.py", line 509, in dispatch
    response = self.handle_exception(exc)
  File "/Library/Frameworks/Python.framework/Versions/3.8/lib/python3.8/site-packages/rest_framework/views.py", line 469, in handle_exception
    self.raise_uncaught_exception(exc)
  File "/Library/Frameworks/Python.framework/Versions/3.8/lib/python3.8/site-packages/rest_framework/views.py", line 480, in raise_uncaught_exception
    raise exc
  File "/Library/Frameworks/Python.framework/Versions/3.8/lib/python3.8/site-packages/rest_framework/views.py", line 506, in dispatch
    response = handler(request, *args, **kwargs)
  File "/Library/Frameworks/Python.framework/Versions/3.8/lib/python3.8/site-packages/rest_framework/mixins.py", line 38, in list
    queryset = self.filter_queryset(self.get_queryset())
  File "/Library/Frameworks/Python.framework/Versions/3.8/lib/python3.8/site-packages/rest_framework/generics.py", line 150, in filter_queryset
    queryset = backend().filter_queryset(self.request, queryset, self)
  File "/Library/Frameworks/Python.framework/Versions/3.8/lib/python3.8/site-packages/rest_framework/filters.py", line 124, in filter_queryset
    queryset = queryset.filter(reduce(operator.and_, conditions))
  File "/Library/Frameworks/Python.framework/Versions/3.8/lib/python3.8/site-packages/django/db/models/query.py", line 1421, in filter
    return self._filter_or_exclude(False, args, kwargs)
  File "/Library/Frameworks/Python.framework/Versions/3.8/lib/python3.8/site-packages/django/db/models/query.py", line 1439, in _filter_or_exclude
    clone._filter_or_exclude_inplace(negate, args, kwargs)
  File "/Library/Frameworks/Python.framework/Versions/3.8/lib/python3.8/site-packages/django/db/models/query.py", line 1446, in _filter_or_exclude_inplace
    self._query.add_q(Q(*args, **kwargs))
  File "/Library/Frameworks/Python.framework/Versions/3.8/lib/python3.8/site-packages/django/db/models/sql/query.py", line 1532, in add_q
    clause, _ = self._add_q(q_object, self.used_aliases)
  File "/Library/Frameworks/Python.framework/Versions/3.8/lib/python3.8/site-packages/django/db/models/sql/query.py", line 1562, in _add_q
    child_clause, needed_inner = self.build_filter(
  File "/Library/Frameworks/Python.framework/Versions/3.8/lib/python3.8/site-packages/django/db/models/sql/query.py", line 1388, in build_filter
    return self._add_q(
  File "/Library/Frameworks/Python.framework/Versions/3.8/lib/python3.8/site-packages/django/db/models/sql/query.py", line 1562, in _add_q
    child_clause, needed_inner = self.build_filter(
  File "/Library/Frameworks/Python.framework/Versions/3.8/lib/python3.8/site-packages/django/db/models/sql/query.py", line 1407, in build_filter
    lookups, parts, reffed_expression = self.solve_lookup_type(arg)
  File "/Library/Frameworks/Python.framework/Versions/3.8/lib/python3.8/site-packages/django/db/models/sql/query.py", line 1217, in solve_lookup_type
    _, field, _, lookup_parts = self.names_to_path(lookup_splitted, self.get_meta())
  File "/Library/Frameworks/Python.framework/Versions/3.8/lib/python3.8/site-packages/django/db/models/sql/query.py", line 1709, in names_to_path
    raise FieldError(
django.core.exceptions.FieldError: Cannot resolve keyword 'test' into field. Choices are: client_statut, company_name, contract, creation_date, email, first_name, id, last_name, mobile, modified_date, phone, sales_contact, sales_contact_id
